<?xml version="1.0" encoding="utf-8"?>
<mujoco>
	<compiler angle="radian"></compiler>
	<size njmax="400" nconmax="100" nuser_jnt="1" nuser_site="1" nuser_tendon="1" nuser_sensor="1" nuser_actuator="16" nstack="600000"></size>
	<option timestep="0.01" iterations="20" apirate="200" noslip_iterations="20"  impratio="1"></option>
	<asset>
		<material name="self" rgba=".7 .5 .3 0.1"/>		
		<texture builtin="gradient" height="100" rgb1="1 1 1" rgb2="0 0 0" type="skybox" width="100"/>
		<texture name="texplane" type="2d" builtin="checker" rgb1=".2 .3 .4" rgb2=".1 0.15 0.2" width="512" height="512"></texture>
		<material name="MatGnd" reflectance="0.5" texture="texplane" texrepeat="2 2" texuniform="true"></material>
		<material name="MatPlane" reflectance="0.05" texture="texplane" texrepeat="1 1" texuniform="true"></material>
	</asset>
	<default>
		<default class="Adroit">
			<geom friction="1 0.005 0.001" condim="3" margin="0.000" contype="1" conaffinity="1"></geom>
			<joint limited="true" damping="0.05" armature=".001" margin="0.01" frictionloss="0.001"></joint>
			<tendon limited="true"></tendon>
			<site size="0.005" rgba=".4 .9 .4 0"></site>
			<default class="D_Touch">
				<site type="box" size="0.009 0.004 0.013" pos="0 -.004 .018" rgba=".8 .8 .8 .15" group="4"></site>
			</default>
			<default class="DC_Hand">
				<geom contype="1" conaffinity="0" material="self" group="2"></geom>
			</default>
		</default>
	</default>
	
	

	<actuator>
        <motor name="A_UARM1"  joint="UARM1" ctrlrange="-100   100" gear = "1"/>
        <motor name="A_UARM2"  joint="UARM2" ctrlrange="-100   100" gear = "1"/>
        <motor name="A_UARM3"  joint="UARM3" ctrlrange="-100   100" gear = "1"/>
        <motor name="A_FARM1"  joint="FARM1" ctrlrange="-100   100" gear = "1"/>
        <motor name="A_WRJ0" user="2036" joint="WRJ0" ctrlrange="-50   50" gear="1"/>
        <motor name="A_WRJ1" user="2038" joint="WRJ1" ctrlrange="-50   50" gear="1"/>
        <motor name="A_WRJ2" joint="WRJ2" ctrlrange="-50   50" gear="1"/>
    </actuator>

	<worldbody>
		<light diffuse="1 1 1" dir="-0 0 -1.3" directional="true" exponent="1" pos="0 0 1.3" specular=".1 .1 .1" castshadow = "false"/>
		<geom name="ground" pos="0 0 0" size="1 1 5" material="MatGnd" type="plane" contype="1" conaffinity="1"></geom>
			<body name="hand mount" pos="0 -.45 0.2" euler="-1.57079632 0 0">
			<inertial mass="0.100" pos="0 0 0" diaginertia="0.001 0.001 0.001"></inertial>
			<body name = "upperarm" childclass = "Adroit" pos = "0 -0.2 0">
				<geom  name="C_upperasrm1" type="sphere" size = '0.001' pos="0 0 0 " class = 'DC_Hand'/>
				<joint name="UARM1" type="hinge" pos="0 0 0" axis="1 0 0" range="-1.57 1.57" damping="0" armature="1"/>
				<body name = 'upperarm2' pos = '0 0 0'>
					<joint name="UARM2" type="hinge" pos="0 0 0" axis="0 0 1" range="-1.57 0" damping="0" armature="1"/>
					<geom  name="C_upperarm2" type="sphere" size = '0.001' pos="0 0 0 " class = 'DC_Hand'/>
					<body name = 'upperarm3' pos = '0 0 0'>
						<joint name="UARM3" type="hinge" pos="0 0 0" axis="0 -1 0" range="-1.57 1.57" damping="0" armature="1"/>
						<geom class="DC_Hand" name="C_upperarm" type="capsule" size = '0.035 0.15 ' pos="0 0.15 0" euler="-1.57 0 0" />
							<body name="forearm" childclass="Adroit" pos="0 0.3 0" euler="0 0 0">
								<inertial pos="0.001 -0.002 0.15" quat="0.982 -0.016 0.000 -0.188" mass="4" diaginertia="0.01 0.01 0.0075" />
								<joint name="FARM1" type="hinge" pos="0 0 0" axis="1 0 0" range="-1.57 1.57" damping="0" armature="1"/>
								<geom class="DC_Hand" name="C_forearm" type="capsule" size = '0.03 0.12 ' pos="0 -.0 0.15" euler="0 0 -1.57" />
								<!-- ======= Wrist ======= -->
								<body name="wrist" pos="0 0 0.3">
									<inertial pos="0.003 0.000 0.016" quat="0.504 0.496 0.495 0.504" mass="0.3" diaginertia="0.001 0.001 0.001" />
									<joint name="WRJ0" type="hinge" pos="0 0 0" axis="1 0 0" range="-1 1" damping="0" armature=".005" user="1122"/>
									<body name = 'wrist1' pos= '0 0 0'>
										<joint name="WRJ1" type="hinge" pos="0 0 0" axis="0 1 0" range="-1.2 1.2" damping="0" armature=".005" user="1123"/>
										<geom  name="C_wrist1" type="sphere" size = '0.001' pos="0 0 0 " class = 'DC_Hand'/>
											<body name = 'wrist2' pos = '0 0 0'>
												<joint name="WRJ2" type="hinge" pos="0 0 0" axis="0 0 1" range="-3.14 0" damping="0" armature=".005"/>
												<geom class="DC_Hand" name="C_wrist" type="sphere" pos="0 0 0.01"  quat=".707 .707 0 0" size=".025" />
												<body name="palm" pos="0 0 0.034">
													<geom class="DC_Hand" name="C_palm" type="sphere" pos="0 0 0.0"  quat=".707 .707 0 0" size=".01" />
												</body>
											</body>		
									</body> <!--Palm Ends-->
								</body> <!--Wrist Ends-->
							</body> <!--Forearm/ Hand Actuation Ends-->
					</body>
				</body>
			</body>
		</body>
	</worldbody>
</mujoco>