<?xml version="1.0" encoding="utf-8"?>
<mujoco>
	<compiler angle="radian"></compiler>
	<size njmax="400" nconmax="100" nuser_jnt="1" nuser_site="1" nuser_tendon="1" nuser_sensor="1" nuser_actuator="16" nstack="600000"></size>
	<option timestep="0.01" iterations="20" apirate="200" noslip_iterations="20"  impratio="10"></option>
	<asset>
		<material name="self" rgba=".7 .5 .3 0.1"/>		
		<texture builtin="gradient" height="100" rgb1="1 1 1" rgb2="0 0 0" type="skybox" width="100"/>
		<texture name="texplane" type="2d" builtin="checker" rgb1=".2 .3 .4" rgb2=".1 0.15 0.2" width="512" height="512"></texture>
		<material name="MatGnd" reflectance="0.5" texture="texplane" texrepeat="2 2" texuniform="true"></material>
		<material name="MatPlane" reflectance="0.05" texture="texplane" texrepeat="1 1" texuniform="true"></material>
	</asset>
	<default>
		<default class="Adroit">
			<geom friction="1 0.005 0.001" condim="3" margin="0.0005" contype="1" conaffinity="1"></geom>
			<joint limited="true" damping="0.05" armature=".001" margin="0.01" frictionloss="0.001"></joint>
			<tendon limited="true"></tendon>
			<site size="0.005" rgba=".4 .9 .4 0"></site>
			<default class="D_Touch">
				<site type="box" size="0.009 0.004 0.013" pos="0 -.004 .018" rgba=".8 .8 .8 .15" group="4"></site>
			</default>
			<default class="DC_Hand">
				<geom contype="1" conaffinity="0" material="self" group="2"></geom>
			</default>
		</default>
	</default>
	

	<worldbody>
		<light diffuse="1 1 1" dir="-0 0 -1.3" directional="true" exponent="1" pos="0 0 1.3" specular=".1 .1 .1" castshadow = "false"/>
		<geom name="ground" pos="0 0 0" size="1 1 5" material="MatGnd" type="plane" contype="1" conaffinity="1"></geom>
        <body name = "chopstick2" pos = "0 0 0.2">
            <joint name="chopstick2" armature=".0001" type="free"></joint>
			<geom class="DC_Hand" name="C_hand" type="sphere" pos="0 0 0.0"  quat=".707 .707 0 0" size=".05" />
            <geom name="chopstick2" density="1000" condim="4" size="0.004 0.13" pos="0.0 -0.0 0.0" type="capsule"  quat="0.707 0 0.707 0" friction="1 0.005 0.0001" rgba="0  0.5 0. 0.5"></geom>
            <site name="origin" pos="-0. 0.0 0.0" size=".0041" type="sphere" rgba="1 0 0 1."></site>
            <site name="end2" pos="-0.13 0.0 0.00" size=".0041" type="sphere" rgba = '1 0 0 1'></site>
            <body name="chopstick1" pos="0.045 0.035 0.0">
                <joint name="Rz1" armature=".01" type="hinge" pos="0 0 0" axis="0 0 1" range="-0.2 0.2"></joint>
                <geom name="chopstick1" density="1000" condim="4" size="0.004 0.13" pos="-0.045 -0.0 0.0" type="capsule" quat="0.707 0 0.707 0" friction="1 0.005 0.0001" rgba="0  0.5 0. 0.5"></geom>
                <site name="c_thtip" pos="0.0 0.0 0.0025" size=".004" type="sphere" rgba="1 0 0 1"></site>
                <site name="c_mftip" pos="-0.04 0.0 -0.0025" size=".004" type="sphere" rgba="1 0 0 1"></site>
                <site name="c_fftip" pos="-0.025 0.0025 0.00" size=".004" type="sphere" rgba="1 0 0 1"></site>
                <site name="end1" pos="-0.175 0.0 0.0" size=".0041" type="sphere" rgba = '1 0 0 1'></site>
            </body>
        </body>
        <body name="object" pos="-0.2 0.2 0.01">
			<joint name="object" type="free" armature="0.0001"></joint>
			<geom name="object" size="0.01" pos="0 0 0" type="sphere" rgba="0 1 0 1" quat="0.707 0 0.707 0"></geom>
		</body>
	</worldbody>
</mujoco>